Workbook

Sheet Instructions
A1: Purpose:
A2: To determine the benefits and total resources (benefits + earned income) available to clients at different earned income levels. To determine the change in benefits and total resources as clients move from one earned income level to another.
A4: ***IMPORTANT DISCLAIMER****
A5: This calculator has the following built in assumptions that may not be applicable for all family situations: ▪ The household has no more than 8 members ▪ There are no child(ren) only cases ▪ All children are blood related or adoptive siblings ▪ There are no step-parents in the household ▪ There are no minor parents ▪ The household is eligible for all selected benefits ▪ The household did not have any countable resources ▪ There is no self-employment income ▪ The children are assumed to be eligible to be claimed as dependents for the household adult and will not be claimed as dependents on anyone else's tax return ▪ There are no child support payments ▪ Children do not have any income ▪ The household does not take the TANF child care/incapacitated adult deduction ▪ Childcare will be provided at a Level 1 Center-based program ▪ The family is not homeless ▪ All household members reside in the home ▪ The family does not live in a group home/institution ▪ There is no unreimbursed: 1)medical care for elderly or disabled individuals, 2) expenses allowing a disabled person to work that exceeds 3% of annual income ▪ Any adult receiving SSI/SSDI is not working ▪ There is no employer-provided health insurance ▪ The second lowest cost Silver plan (SLCSP) was selected on the CoverVA website with no cost-sharing ▪ The calculations for the housing choice voucher do not include a childcare deduction ▪ The rental unit size is based on 2 ppl/bedroom (adults and children separate) ▪ Initial housing choice voucher income limits are 50% of AMI, new income are not subjected to an income check ▪ Utilities are not inclded in the rent ▪ No adults are eligible for WIC-only children <5 years old-no pregnant women
A7: Instructions
A8: Hunter Sm
A10: Data Sources
A11: Child Care Subsidy rates sourced from: https://fusion.dss.virginia.gov/Portals/[ccecd]/T224%20Child%20Care%20Subsidy%20Program%20Manual_Effective%20October%201_2024.pdf?ver=2024-09-30-111401-117 Rates updated 7/1/2025 https://www.childcare.virginia.gov/home/showpublisheddocument/62604/638864381965000000
A12: Federal EITC Calculated using https://apps.irs.gov/app/eitc/results/, state EITC calculated using https://www.tax.virginia.gov/low-income-individuals-credit
A13: SLCSP sourced from https://enroll.marketplace.virginia.gov/hix/preeligibility#/
A14: Housing Choice Voucher rates sources from10/10/2024 https://www.huduser.gov/portal/datasets/il/il2024/2024summary.odn., https://www.huduser.gov/portal/datasets/fmr/fmrs/FY2024_code/select_Geography.odn, https://www.virginiahousing.com/partners/housing-choice-vouchers/payment-standards Income limits: https://www.huduser.gov/portal/datasets/il.html#data_2025 FY 2024 Fair Market Rent Documentation System: https://www.huduser.gov/portal/datasets/fmr/fmrs/FY2025_code/2025state_summary.odn HCV calculations sourced from https://www.hud.gov/sites/dfiles/PIH/documents/HCV_Guidebook_Calculating_Rent_and_HAP_Payments.pdf
A15: Medicaid income limits sourced from: https://fusion.dss.virginia.gov/Portals/%5Bbp%5D/Medicaid/Resources%20and%20Job%20Aids/01.20.24%20Income%20Limits.docx Medicaid benefit determined by averaging state and federal spending per Medicaid enrollee, sourced from Federa Reserve Bank of Atlanta at https://emar-data-tools.shinyapps.io/prd_dashboard/
... A29: SSI basic monthly payment : https://www.ssa.gov/pubs/EN-05-11002.pdf

Sheet Total income package
A1: Location Information
A2: Locality | B2: Select from drop-down menu
B3: Buckingham
A5: Benefits Information
A6: Select benefit programs
A8: TRUE
C9: At least one adult must have earned income to select EITC At least one tax filer must be between 25-64 years if claiming EITC credit AND have no qualifying children
A10: TRUE
A12: TRUE
C13: If housing choice voucher is selected-how many bedrooms is the unit? Select from drop down list | D13: 4 | E13: s
A14: TRUE
A16: TRUE
A18: TRUE
C19: If choosing TANF benefits-select only one TANF program (TANF or TANF/VIEW)
A20: TRUE
A22: FALSE
A24: TRUE
A26: Household Information
A27: Calculator valid for households up to 8 people
A30: Number of adults in household | B30: 3 | C30: Include adults and children receiving SSI/SSDI
A31: Number of children ( 18 years old or less) in household | B31: 2
A32: Total number of people in household (Calculated) | B32: =IF(B30+B31>8,"Only valid for up to 8 people",B30+B31) -> 5
A35: Age(s) of Household Members
A36: Age(s) of adult(s): | B36: Enter age (in years)
A37: Adult 1 | B37: 34 | C37: Is this adult a parent of any of the children listed below? Select yes or no. | E37: Yes
A38: Adult 2 | B38: 28 | C38: Is this adult a parent of any of the children listed below? Select yes or no. | E38: Yes
A39: Adult 3 | B39: 80 | C39: Is this adult a parent of any of the children listed below? Select yes or no. | E39: No
A40: Adult 4 | C40: Is this adult a parent of any of the children listed below? Select yes or no. | E40: No
A41: Adult 5 | C41: Is this adult a parent of any of the children listed below? Select yes or no.
A42: Adult 6 | C42: Is this adult a parent of any of the children listed below? Select yes or no.
A43: Adult 7 | C43: Is this adult a parent of any of the children listed below? Select yes or no.
A44: Adult 8 | C44: Is this adult a parent of any of the children listed below? Select yes or no.
A46: Age categories of children (The number of children listed here should match the number of children in the household above.) | B46: Select from drop-down menu | C46: For children: Select: "Infant" if child is 16 months or younger "Toddler" if child is 16-23 months "Two year old" if child is 24-36 months "Prechool" if child is 36 months to 5 years and not yet in kindergarten "School age" if child is eligible to attend public school but less than 13 years "13 years or older" if child is 13 years or older and capable of caring from themselves "13-18" years old if child is physically or mentally incapable of caring for themselves
A48: Child 1 | B48: School age
A49: Child 2 | B49: Infant
A50: Child 3
A51: Child 4
A52: Child 5
A53: Child 6
A54: Child 7
...

Sheet Income conversions
A1: Convert hourly wage to monthly income
A2: Hourly wage | B2: 12
A3: How many hours (total) worked in a month | B3: 20
A5: Monthly earned income (gross) | B5: =B2*B3 -> 240
A6: Annual earned income (gross) | B6: =B5*12 -> 2880
A8: Convert annual income to monthly income
A9: Annual income (gross) | B9: 30000
A10: Monthly earned income (gross) | B10: =B9/12 -> 2500
A13: Return to Total Income tab

Sheet Use this for graphs
A1: Annual earned income | B1: Monthly earned income | C1: Annual Child Care Subsidy | D1: TANF | E1: Annual SNAP Benefit | F1: Annual WIC Benefit | G1: Housing Choice Voucher | H1: Fed + State EITC | I1: Value of Medicaid | J1: Value of Marketplace Subsidies | K1: Total benefits | L1: Total benefits + income
A2: 0 | B2: =A2/12 -> 0 | C2: ='Child care subsidy'!S5*12 -> 24000 | D2: =MAX('TANF-VIEW'!L9,'TANF-VIEW'!T9)*12 -> 4620 | E2: =SNAP!V6*12 -> 14196 | F2: =WIC!F8*12 -> 441.12 | G2: ='Housing Voucher'!Q6*12 -> 16049.988 | H2: =EITC!E5 -> 0 | I2: =Medicaid!N9*12 -> 26265 | K2: =SUM(C2:I2) -> 85572.108 | L2: =A2+K2 -> 85572.108 | M2: =L2/12 -> 7131.009
A3: 500 | B3: =A3/12 -> 41.666667 | C3: ='Child care subsidy'!S6*12 -> 23975 | D3: =MAX('TANF-VIEW'!L10,'TANF-VIEW'!T10)*12 -> 4620 | E3: =SNAP!V7*12 -> 14196 | F3: =WIC!F9*12 -> 441.12 | G3: ='Housing Voucher'!Q7*12 -> 15899.988 | H3: =EITC!E6 -> 240 | I3: =Medicaid!N10*12 -> 26265 | K3: =SUM(C3:I3) -> 85637.108 | L3: =A3+K3 -> 86137.108 | M3: =L3/12 -> 7178.0923
A4: 1000 | B4: =A4/12 -> 83.333333 | C4: ='Child care subsidy'!S7*12 -> 23950 | D4: =MAX('TANF-VIEW'!L11,'TANF-VIEW'!T11)*12 -> 4620 | E4: =SNAP!V8*12 -> 14196 | F4: =WIC!F10*12 -> 441.12 | G4: ='Housing Voucher'!Q8*12 -> 15749.988 | H4: =EITC!E7 -> 480 | I4: =Medicaid!N11*12 -> 26265 | K4: =SUM(C4:I4) -> 85702.108 | L4: =A4+K4 -> 86702.108 | M4: =L4/12 -> 7225.1757
A5: 1500 | B5: =A5/12 -> 125 | C5: ='Child care subsidy'!S8*12 -> 23925 | D5: =MAX('TANF-VIEW'!L12,'TANF-VIEW'!T12)*12 -> 4620 | E5: =SNAP!V9*12 -> 14196 | F5: =WIC!F11*12 -> 441.12 | G5: ='Housing Voucher'!Q9*12 -> 15599.988 | H5: =EITC!E8 -> 720 | I5: =Medicaid!N12*12 -> 26265 | K5: =SUM(C5:I5) -> 85767.108 | L5: =A5+K5 -> 87267.108 | M5: =L5/12 -> 7272.259
A6: 2000 | B6: =A6/12 -> 166.66667 | C6: ='Child care subsidy'!S9*12 -> 23900 | D6: =MAX('TANF-VIEW'!L13,'TANF-VIEW'!T13)*12 -> 4620 | E6: =SNAP!V10*12 -> 14196 | F6: =WIC!F12*12 -> 441.12 | G6: ='Housing Voucher'!Q10*12 -> 15449.988 | H6: =EITC!E9 -> 960 | I6: =Medicaid!N13*12 -> 26265 | K6: =SUM(C6:I6) -> 85832.108 | L6: =A6+K6 -> 87832.108 | M6: =L6/12 -> 7319.3423
A7: 2500 | B7: =A7/12 -> 208.33333 | C7: ='Child care subsidy'!S10*12 -> 23875 | D7: =MAX('TANF-VIEW'!L14,'TANF-VIEW'!T14)*12 -> 4620 | E7: =SNAP!V11*12 -> 14196 | F7: =WIC!F13*12 -> 441.12 | G7: ='Housing Voucher'!Q11*12 -> 15299.988 | H7: =EITC!E10 -> 1200 | I7: =Medicaid!N14*12 -> 26265 | K7: =SUM(C7:I7) -> 85897.108 | L7: =A7+K7 -> 88397.108 | M7: =L7/12 -> 7366.4257
A8: 3000 | B8: =A8/12 -> 250 | C8: ='Child care subsidy'!S11*12 -> 23850 | D8: =MAX('TANF-VIEW'!L15,'TANF-VIEW'!T15)*12 -> 4226.4 | E8: =SNAP!V12*12 -> 14196 | F8: =WIC!F14*12 -> 441.12 | G8: ='Housing Voucher'!Q12*12 -> 15268.068 | H8: =EITC!E11 -> 1440 | I8: =Medicaid!N15*12 -> 26265 | K8: =SUM(C8:I8) -> 85686.588 | L8: =A8+K8 -> 88686.588 | M8: =L8/12 -> 7390.549
A9: 3500 | B9: =A9/12 -> 291.66667 | C9: ='Child care subsidy'!S12*12 -> 23825 | D9: =MAX('TANF-VIEW'!L16,'TANF-VIEW'!T16)*12 -> 3826.4 | E9: =SNAP!V13*12 -> 14196 | F9: =WIC!F15*12 -> 441.12 | G9: ='Housing Voucher'!Q13*12 -> 15238.068 | H9: =EITC!E12 -> 1680 | I9: =Medicaid!N16*12 -> 26265 | K9: =SUM(C9:I9) -> 85471.588 | L9: =A9+K9 -> 88971.588 | M9: =L9/12 -> 7414.299
A10: 4000 | B10: =A10/12 -> 333.33333 | C10: ='Child care subsidy'!S13*12 -> 23800 | D10: =MAX('TANF-VIEW'!L17,'TANF-VIEW'!T17)*12 -> 3426.4 | E10: =SNAP!V14*12 -> 14196 | F10: =WIC!F16*12 -> 441.12 | G10: ='Housing Voucher'!Q14*12 -> 15208.068 | H10: =EITC!E13 -> 1920 | I10: =Medicaid!N17*12 -> 26265 | K10: =SUM(C10:I10) -> 85256.588 | L10: =A10+K10 -> 89256.588 | M10: =L10/12 -> 7438.049
A11: 4500 | B11: =A11/12 -> 375 | C11: ='Child care subsidy'!S14*12 -> 23775 | D11: =MAX('TANF-VIEW'!L18,'TANF-VIEW'!T18)*12 -> 3026.4 | E11: =SNAP!V15*12 -> 14196 | F11: =WIC!F17*12 -> 441.12 | G11: ='Housing Voucher'!Q15*12 -> 15178.068 | H11: =EITC!E14 -> 2160 | I11: =Medicaid!N18*12 -> 26265 | K11: =SUM(C11:I11) -> 85041.588 | L11: =A11+K11 -> 89541.588 | M11: =L11/12 -> 7461.799
A12: 5000 | B12: =A12/12 -> 416.66667 | C12: ='Child care subsidy'!S15*12 -> 23760 | D12: =MAX('TANF-VIEW'!L19,'TANF-VIEW'!T19)*12 -> 2626.4 | E12: =SNAP!V16*12 -> 14196 | F12: =WIC!F18*12 -> 441.12 | G12: ='Housing Voucher'!Q16*12 -> 15148.068 | H12: =EITC!E15 -> 2400 | I12: =Medicaid!N19*12 -> 26265 | K12: =SUM(C12:I12) -> 84836.588 | L12: =A12+K12 -> 89836.588 | M12: =L12/12 -> 7486.3823
A13: 5500 | B13: =A13/12 -> 458.33333 | C13: ='Child care subsidy'!S16*12 -> 23760 | D13: =MAX('TANF-VIEW'!L20,'TANF-VIEW'!T20)*12 -> 2226.4 | E13: =SNAP!V17*12 -> 14196 | F13: =WIC!F19*12 -> 441.12 | G13: ='Housing Voucher'!Q17*12 -> 15118.068 | H13: =EITC!E16 -> 2640 | I13: =Medicaid!N20*12 -> 26265 | K13: =SUM(C13:I13) -> 84646.588 | L13: =A13+K13 -> 90146.588 | M13: =L13/12 -> 7512.2157
... A132: 65000 | B132: =A132/12 -> 5416.6667 | C132: ='Child care subsidy'!S135*12 -> 20750 | D132: =MAX('TANF-VIEW'!L139,'TANF-VIEW'!T139)*12 -> 0 | E132: =SNAP!V136*12 -> 0 | F132: =WIC!F138*12 -> 441.12 | G132: ='Housing Voucher'!Q136*12 -> 0 | H132: =EITC!E135 -> 0 | I132: =Medicaid!N139*12 -> 7644 | K132: =SUM(C132:I132) -> 28835.12 | L132: =A132+K132 -> 93835.12 | M132: =L132/12 -> 7819.5933
A133: 65500 | B133: =A133/12 -> 5458.3333 | C133: ='Child care subsidy'!S136*12 -> 20725 | D133: =MAX('TANF-VIEW'!L140,'TANF-VIEW'!T140)*12 -> 0 | E133: =SNAP!V137*12 -> 0 | F133: =WIC!F139*12 -> 441.12 | G133: ='Housing Voucher'!Q137*12 -> 0 | H133: =EITC!E136 -> 0 | I133: =Medicaid!N140*12 -> 7644 | K133: =SUM(C133:I133) -> 28810.12 | L133: =A133+K133 -> 94310.12 | M133: =L133/12 -> 7859.1767 | P133: =C135/12 -> 1722.9167
A134: 66000 | B134: =A134/12 -> 5500 | C134: ='Child care subsidy'!S137*12 -> 20700 | D134: =MAX('TANF-VIEW'!L141,'TANF-VIEW'!T141)*12 -> 0 | E134: =SNAP!V138*12 -> 0 | F134: =WIC!F140*12 -> 441.12 | G134: ='Housing Voucher'!Q138*12 -> 0 | H134: =EITC!E137 -> 0 | I134: =Medicaid!N141*12 -> 7644 | K134: =SUM(C134:I134) -> 28785.12 | L134: =A134+K134 -> 94785.12 | M134: =L134/12 -> 7898.76
A135: 66500 | B135: =A135/12 -> 5541.6667 | C135: ='Child care subsidy'!S138*12 -> 20675 | D135: =MAX('TANF-VIEW'!L142,'TANF-VIEW'!T142)*12 -> 0 | E135: =SNAP!V139*12 -> 0 | F135: =WIC!F141*12 -> 441.12 | G135: ='Housing Voucher'!Q139*12 -> 0 | H135: =EITC!E138 -> 0 | I135: =Medicaid!N142*12 -> 7644 | K135: =SUM(C135:I135) -> 28760.12 | L135: =A135+K135 -> 95260.12 | M135: =L135/12 -> 7938.3433
A136: 67000 | B136: =A136/12 -> 5583.3333 | C136: ='Child care subsidy'!S139*12 -> 20650 | D136: =MAX('TANF-VIEW'!L143,'TANF-VIEW'!T143)*12 -> 0 | E136: =SNAP!V140*12 -> 0 | F136: =WIC!F142*12 -> 0 | G136: ='Housing Voucher'!Q140*12 -> 0 | H136: =EITC!E139 -> 0 | I136: =Medicaid!N143*12 -> 7644 | K136: =SUM(C136:I136) -> 28294 | L136: =A136+K136 -> 95294 | M136: =L136/12 -> 7941.1667
A137: 67500 | B137: =A137/12 -> 5625 | C137: ='Child care subsidy'!S140*12 -> 20625 | D137: =MAX('TANF-VIEW'!L144,'TANF-VIEW'!T144)*12 -> 0 | E137: =SNAP!V141*12 -> 0 | F137: =WIC!F143*12 -> 0 | G137: ='Housing Voucher'!Q141*12 -> 0 | H137: =EITC!E140 -> 0 | I137: =Medicaid!N144*12 -> 7644 | K137: =SUM(C137:I137) -> 28269 | L137: =A137+K137 -> 95769 | M137: =L137/12 -> 7980.75
A138: 68000 | B138: =A138/12 -> 5666.6667 | C138: ='Child care subsidy'!S141*12 -> 20600 | D138: =MAX('TANF-VIEW'!L145,'TANF-VIEW'!T145)*12 -> 0 | E138: =SNAP!V142*12 -> 0 | F138: =WIC!F144*12 -> 0 | G138: ='Housing Voucher'!Q142*12 -> 0 | H138: =EITC!E141 -> 0 | I138: =Medicaid!N145*12 -> 7644 | K138: =SUM(C138:I138) -> 28244 | L138: =A138+K138 -> 96244 | M138: =L138/12 -> 8020.3333
A139: 68500 | B139: =A139/12 -> 5708.3333 | C139: ='Child care subsidy'!S142*12 -> 20575 | D139: =MAX('TANF-VIEW'!L146,'TANF-VIEW'!T146)*12 -> 0 | E139: =SNAP!V143*12 -> 0 | F139: =WIC!F145*12 -> 0 | G139: ='Housing Voucher'!Q143*12 -> 0 | H139: =EITC!E142 -> 0 | I139: =Medicaid!N146*12 -> 7644 | K139: =SUM(C139:I139) -> 28219 | L139: =A139+K139 -> 96719 | M139: =L139/12 -> 8059.9167
A140: 69000 | B140: =A140/12 -> 5750 | C140: ='Child care subsidy'!S143*12 -> 20550 | D140: =MAX('TANF-VIEW'!L147,'TANF-VIEW'!T147)*12 -> 0 | E140: =SNAP!V144*12 -> 0 | F140: =WIC!F146*12 -> 0 | G140: ='Housing Voucher'!Q144*12 -> 0 | H140: =EITC!E143 -> 0 | I140: =Medicaid!N147*12 -> 7644 | K140: =SUM(C140:I140) -> 28194 | L140: =A140+K140 -> 97194 | M140: =L140/12 -> 8099.5
A141: 69500 | B141: =A141/12 -> 5791.6667 | C141: ='Child care subsidy'!S144*12 -> 20525 | D141: =MAX('TANF-VIEW'!L148,'TANF-VIEW'!T148)*12 -> 0 | E141: =SNAP!V145*12 -> 0 | F141: =WIC!F147*12 -> 0 | G141: ='Housing Voucher'!Q145*12 -> 0 | H141: =EITC!E144 -> 0 | I141: =Medicaid!N148*12 -> 7644 | K141: =SUM(C141:I141) -> 28169 | L141: =A141+K141 -> 97669 | M141: =L141/12 -> 8139.0833
A142: 70000 | B142: =A142/12 -> 5833.3333 | C142: ='Child care subsidy'!S145*12 -> 20500 | D142: =MAX('TANF-VIEW'!L149,'TANF-VIEW'!T149)*12 -> 0 | E142: =SNAP!V146*12 -> 0 | F142: =WIC!F148*12 -> 0 | G142: ='Housing Voucher'!Q146*12 -> 0 | H142: =EITC!E145 -> 0 | I142: =Medicaid!N149*12 -> 7644 | K142: =SUM(C142:I142) -> 28144 | L142: =A142+K142 -> 98144 | M142: =L142/12 -> 8178.6667
A143: 70500 | B143: =A143/12 -> 5875 | C143: ='Child care subsidy'!S146*12 -> 20475 | D143: =MAX('TANF-VIEW'!L150,'TANF-VIEW'!T150)*12 -> 0 | E143: =SNAP!V147*12 -> 0 | F143: =WIC!F149*12 -> 0 | G143: ='Housing Voucher'!Q147*12 -> 0 | H143: =EITC!E146 -> 0 | I143: =Medicaid!N150*12 -> 7644 | K143: =SUM(C143:I143) -> 28119 | L143: =A143+K143 -> 98619 | M143: =L143/12 -> 8218.25
A144: 71000 | B144: =A144/12 -> 5916.6667 | C144: ='Child care subsidy'!S147*12 -> 20450 | D144: =MAX('TANF-VIEW'!L151,'TANF-VIEW'!T151)*12 -> 0 | E144: =SNAP!V148*12 -> 0 | F144: =WIC!F150*12 -> 0 | G144: ='Housing Voucher'!Q148*12 -> 0 | H144: =EITC!E147 -> 0 | I144: =Medicaid!N151*12 -> 7644 | K144: =SUM(C144:I144) -> 28094 | L144: =A144+K144 -> 99094 | M144: =L144/12 -> 8257.8333
A145: 71500 | B145: =A145/12 -> 5958.3333 | C145: ='Child care subsidy'!S148*12 -> 20425 | D145: =MAX('TANF-VIEW'!L152,'TANF-VIEW'!T152)*12 -> 0 | E145: =SNAP!V149*12 -> 0 | F145: =WIC!F151*12 -> 0 | G145: ='Housing Voucher'!Q149*12 -> 0 | H145: =EITC!E148 -> 0 | I145: =Medicaid!N152*12 -> 7644 | K145: =SUM(C145:I145) -> 28069 | L145: =A145+K145 -> 99569 | M145: =L145/12 -> 8297.4167
... A202: 100000 | B202: =A202/12 -> 8333.3333 | C202: ='Child care subsidy'!S205*12 -> 17000 | D202: =MAX('TANF-VIEW'!L209,'TANF-VIEW'!T209)*12 -> 0 | E202: =SNAP!V206*12 -> 0 | F202: =WIC!F208*12 -> 0 | G202: ='Housing Voucher'!Q206*12 -> 0 | H202: =EITC!E205 -> 0 | I202: =Medicaid!N209*12 -> 0 | K202: =SUM(C202:I202) -> 17000 | L202: =A202+K202 -> 117000 | M202: =L202/12 -> 9750

Sheet Data validation
A1: Localities | B1: Benefit programs | E1: Ages | G1: Filing status
A2: Accomack | B2: Child care subsidy | E2: Infant | G2: Married filing jointly
A3: Albemarle | B3: EITC (Fed & State) | E3: Toddler | G3: Single, head of household, qualifying surviving spouse
A4: Alexandria City | B4: Health insurance marketplace subsidies | E4: Two year old
A5: Alleghany | B5: Housing choice voucher | E5: Preschool
A6: Amelia | B6: Medicaid | E6: School age
A7: Amherst | B7: SNAP | E7: 13 years or older | G7: Not valid for >10 household members
A8: Appomattox | B8: TANF | E8: 13-18 years old
A9: Arlington County | B9: TANF/VIEW | G9: # of bedrooms
A10: Augusta | B10: WIC | E10: Addition/Subtraction | G10: 1
A11: Bath | E11: Addition | G11: 2
A12: Bedford | B12: Yes/No | E12: Subtraction | G12: 3
A13: Bland | B13: Yes | G13: 4
A14: Botetourt | B14: No
A15: Bristol | E15: Yes/No ABD
A16: Brunswick | E16: Yes-aged
A17: Buchanan | E17: Yes-blind
A18: Buckingham | B18: Incomes | E18: Yes-disabled
A19: Buena Vista | B19: 0 | E19: No
A20: Campbell | B20: 1000
A21: Caroline | B21: 2000
A22: Carroll | B22: 3000 | E22: SUA
A23: Charles City | B23: 4000 | E23: Standard Utility Allowance (SUA)
A24: Charlotte | B24: 5000 | E24: Actual monthly utility costs
A25: Charlottesville City | B25: 6000
A26: Chesapeake | B26: 7000
A27: Chesterfield | B27: 8000
A28: Clarke | B28: 9000
A29: Colonial Heights | B29: 10000
A30: Covington | B30: 11000
A31: Craig | B31: 12000
A32: Culpeper | B32: 13000
A33: Cumberland | B33: 14000
A34: Danville city | B34: 15000
A35: Dickenson County | B35: 16000
A36: Dinwiddie | B36: 17000
... A119: Stafford | B119: 100000
A120: Staunton City
A121: Suffolk
A122: Surry
...

Sheet Graphs

Sheet Child care subsidy
A1: Location | B1: Number in Household | C1: Number of eligible children infant | D1: Number of eligible children toddler | E1: Number of eligible children 2yo | F1: Number of eligible children preschool | G1: Number of eligible children school age | H1: Number of eligible children 13-18 unable to care for themselves | J1: Annual FPL for Household number | K1: Monthly FPL for Household number | M1: Monthly income limit for group and HH size | N1: 85% SMI | O1: Child care disregards SSI, TANF, child earnings if <18 | S1: =1344/20 -> 67.2
A2: ='Total income package'!B3 -> Buckingham | B2: ='Total income package'!B32 -> 5 | C2: =COUNTIF('Total income package'!$B$48:$B$54,"Infant") -> 1 | D2: =COUNTIF('Total income package'!$B$48:$B$54,"Toddler") -> 0 | E2: =COUNTIF('Total income package'!$B$48:$B$54,"Two year old") -> 0 | F2: =COUNTIF('Total income package'!$B$48:$B$54,"Preschool") -> 0 | G2: =COUNTIF('Total income package'!$B$48:$B$54,"School age") -> 1 | H2: =COUNTIF('Total income package'!$B$48:$B$54,"13-18 years old") -> 0 | J2: =VLOOKUP(B2,'Program specific data'!A5:C13,2) -> 38680 | K2: =VLOOKUP(B2,'Program specific data'!A5:C13,3) -> 3223.3333 | M2: =IF(A3=1,VLOOKUP(B2,'Program specific data'!A20:F27,3,FALSE),IF(A3=2,VLOOKUP(B2,'Program specific data'!A20:F27,4,FALSE),IF(A3=3,VLOOKUP(B2,'Program specific data'!A20:F27,5),IF(A3=4,VLOOKUP(B2,'Program specific data'!A20:F27,6,FALSE))))) -> 4835 | N2: =VLOOKUP(B2,'Program specific data'!A20:B27,2) -> 11011
A3: =VLOOKUP('Total income package'!B3,'Location specific data'!A3:AM135,39,FALSE) -> 1 | F3: Level I Care Center Max Reimbursement Rate (Full Day)
A4: Annual earned income | B4: Monthly earned income | C4: Social Security income | D4: Total Income | E4: % FPL | F4: Eligible by 85% SMI & have a child <5 yrs & not started kindergarten? | G4: Eligible by %FPL for locality? | H4: Eligible by in TANF | I4: Monthly copayment per child | J4: Monthly Infant | K4: Monthly Toddler | L4: Monthly 2yo | M4: Monthly Pre-school | N4: Monthly School Age and/or 13-18 unable to care for self | O4: Monthly copay based on number of children | P4: 5% of monthly income | Q4: Copay for 3 children | R4: Family copay if not >5% of income & capped at 3 children | S4: Monthly Child care benefit (Reimbursement - copay) If eligible via SMI, TANF, or FPL and Child Care subsidy is selected
A5: 0 | B5: =A5/12 -> 0 | C5: ='Total income package'!$D$80 -> 0 | D5: =B5+C5 -> 0 | E5: =D5/$K$2 -> 0 | F5: =IF(AND(B5<$N$2,SUM($C$2:$F$2)>0),"Yes","No") -> Yes | G5: =IF(B5<$M$2,"Yes","No") -> Yes | H5: =IF(OR('TANF-VIEW'!L9>0,'TANF-VIEW'!T9>0),"Yes","No") -> Yes | I5: =IF(B5>=$N$2,0,IF(E5>3.5,375*SUM($C$2:$H$2),IF(E5>3,325*SUM($C$2:$H$2),IF(E5>2.5,275*SUM($C$2:$H$2),IF(E5>2,225*SUM($C$2:$H$2),IF(E5>1.5,175*SUM($C$2:$H$2),IF(E5>1,125*SUM($C$2:$H$2),IF(E5>0,5*SUM($C$2:$H$2),0)))))))) -> 0 | J5: =(IF(B5>$N$2,0,VLOOKUP('Total income package'!$B$3,'Location specific data'!$A$3:$AO$135,33,FALSE))*$C$2)*20 -> 1400 | K5: =IF(B5>$N$2,0,VLOOKUP('Total income package'!$B$3,'Location specific data'!$A$3:$AO$135,34,FALSE))*$D$2*20 -> 0 | L5: =IF(B5>$N$2,0,VLOOKUP('Total income package'!$B$3,'Location specific data'!$A$3:$AO$135,35,FALSE))*$E$2*20 -> 0 | M5: =IF(B5>$N$2,0,VLOOKUP('Total income package'!$B$3,'Location specific data'!$A$3:$AO$135,36,FALSE))*$F$2*20 -> 0 | N5: =IF(B5>$N$2,0,VLOOKUP('Total income package'!$B$3,'Location specific data'!$A$3:$AO$135,37,FALSE))*($G$2+$H$2)*20 -> 600 | O5: =I5*SUM($C$2:$H$2) -> 0 | P5: =B5*0.05 -> 0 | Q5: =I5*3 -> 0 | R5: =IF(MIN(O5,P5)<Q5,MIN(O5,P5),Q5) -> 0 | S5: =IF(AND('Total income package'!$A$8=TRUE,OR(F5="Yes",G5="Yes",H5="Yes")),SUM(J5:N5)-R5,0) -> 2000
A6: 500 | B6: =A6/12 -> 41.666667 | C6: ='Total income package'!$D$80 -> 0 | D6: =B6+C6 -> 41.666667 | E6: =D6/$K$2 -> 0.012926577 | F6: =IF(AND(B6<$N$2,SUM($C$2:$F$2)>0),"Yes","No") -> Yes | G6: =IF(B6<$M$2,"Yes","No") -> Yes | H6: =IF(OR('TANF-VIEW'!L10>0,'TANF-VIEW'!T10>0),"Yes","No") -> Yes | I6: =IF(B6>=$N$2,0,IF(E6>3.5,375*SUM($C$2:$H$2),IF(E6>3,325*SUM($C$2:$H$2),IF(E6>2.5,275*SUM($C$2:$H$2),IF(E6>2,225*SUM($C$2:$H$2),IF(E6>1.5,175*SUM($C$2:$H$2),IF(E6>1,125*SUM($C$2:$H$2),IF(E6>0,5*SUM($C$2:$H$2),0)))))))) -> 10 | J6: =(IF(B6>$N$2,0,VLOOKUP('Total income package'!$B$3,'Location specific data'!$A$3:$AO$135,33,FALSE))*$C$2)*20 -> 1400 | K6: =IF(B6>$N$2,0,VLOOKUP('Total income package'!$B$3,'Location specific data'!$A$3:$AO$135,34,FALSE))*$D$2*20 -> 0 | L6: =IF(B6>$N$2,0,VLOOKUP('Total income package'!$B$3,'Location specific data'!$A$3:$AO$135,35,FALSE))*$E$2*20 -> 0 | M6: =IF(B6>$N$2,0,VLOOKUP('Total income package'!$B$3,'Location specific data'!$A$3:$AO$135,36,FALSE))*$F$2*20 -> 0 | N6: =IF(B6>$N$2,0,VLOOKUP('Total income package'!$B$3,'Location specific data'!$A$3:$AO$135,37,FALSE))*($G$2+$H$2)*20 -> 600 | O6: =I6*SUM($C$2:$H$2) -> 20 | P6: =B6*0.05 -> 2.0833333 | Q6: =I6*3 -> 30 | R6: =IF(MIN(O6,P6)<Q6,MIN(O6,P6),Q6) -> 2.0833333 | S6: =IF(AND('Total income package'!$A$8=TRUE,OR(F6="Yes",G6="Yes",H6="Yes")),SUM(J6:N6)-R6,0) -> 1997.9167
A7: 1000 | B7: =A7/12 -> 83.333333 | C7: ='Total income package'!$D$80 -> 0 | D7: =B7+C7 -> 83.333333 | E7: =D7/$K$2 -> 0.025853154 | F7: =IF(AND(B7<$N$2,SUM($C$2:$F$2)>0),"Yes","No") -> Yes | G7: =IF(B7<$M$2,"Yes","No") -> Yes | H7: =IF(OR('TANF-VIEW'!L11>0,'TANF-VIEW'!T11>0),"Yes","No") -> Yes | I7: =IF(B7>=$N$2,0,IF(E7>3.5,375*SUM($C$2:$H$2),IF(E7>3,325*SUM($C$2:$H$2),IF(E7>2.5,275*SUM($C$2:$H$2),IF(E7>2,225*SUM($C$2:$H$2),IF(E7>1.5,175*SUM($C$2:$H$2),IF(E7>1,125*SUM($C$2:$H$2),IF(E7>0,5*SUM($C$2:$H$2),0)))))))) -> 10 | J7: =(IF(B7>$N$2,0,VLOOKUP('Total income package'!$B$3,'Location specific data'!$A$3:$AO$135,33,FALSE))*$C$2)*20 -> 1400 | K7: =IF(B7>$N$2,0,VLOOKUP('Total income package'!$B$3,'Location specific data'!$A$3:$AO$135,34,FALSE))*$D$2*20 -> 0 | L7: =IF(B7>$N$2,0,VLOOKUP('Total income package'!$B$3,'Location specific data'!$A$3:$AO$135,35,FALSE))*$E$2*20 -> 0 | M7: =IF(B7>$N$2,0,VLOOKUP('Total income package'!$B$3,'Location specific data'!$A$3:$AO$135,36,FALSE))*$F$2*20 -> 0 | N7: =IF(B7>$N$2,0,VLOOKUP('Total income package'!$B$3,'Location specific data'!$A$3:$AO$135,37,FALSE))*($G$2+$H$2)*20 -> 600 | O7: =I7*SUM($C$2:$H$2) -> 20 | P7: =B7*0.05 -> 4.1666667 | Q7: =I7*3 -> 30 | R7: =IF(MIN(O7,P7)<Q7,MIN(O7,P7),Q7) -> 4.1666667 | S7: =IF(AND('Total income package'!$A$8=TRUE,OR(F7="Yes",G7="Yes",H7="Yes")),SUM(J7:N7)-R7,0) -> 1995.8333
A8: 1500 | B8: =A8/12 -> 125 | C8: ='Total income package'!$D$80 -> 0 | D8: =B8+C8 -> 125 | E8: =D8/$K$2 -> 0.038779731 | F8: =IF(AND(B8<$N$2,SUM($C$2:$F$2)>0),"Yes","No") -> Yes | G8: =IF(B8<$M$2,"Yes","No") -> Yes | H8: =IF(OR('TANF-VIEW'!L12>0,'TANF-VIEW'!T12>0),"Yes","No") -> Yes | I8: =IF(B8>=$N$2,0,IF(E8>3.5,375*SUM($C$2:$H$2),IF(E8>3,325*SUM($C$2:$H$2),IF(E8>2.5,275*SUM($C$2:$H$2),IF(E8>2,225*SUM($C$2:$H$2),IF(E8>1.5,175*SUM($C$2:$H$2),IF(E8>1,125*SUM($C$2:$H$2),IF(E8>0,5*SUM($C$2:$H$2),0)))))))) -> 10 | J8: =(IF(B8>$N$2,0,VLOOKUP('Total income package'!$B$3,'Location specific data'!$A$3:$AO$135,33,FALSE))*$C$2)*20 -> 1400 | K8: =IF(B8>$N$2,0,VLOOKUP('Total income package'!$B$3,'Location specific data'!$A$3:$AO$135,34,FALSE))*$D$2*20 -> 0 | L8: =IF(B8>$N$2,0,VLOOKUP('Total income package'!$B$3,'Location specific data'!$A$3:$AO$135,35,FALSE))*$E$2*20 -> 0 | M8: =IF(B8>$N$2,0,VLOOKUP('Total income package'!$B$3,'Location specific data'!$A$3:$AO$135,36,FALSE))*$F$2*20 -> 0 | N8: =IF(B8>$N$2,0,VLOOKUP('Total income package'!$B$3,'Location specific data'!$A$3:$AO$135,37,FALSE))*($G$2+$H$2)*20 -> 600 | O8: =I8*SUM($C$2:$H$2) -> 20 | P8: =B8*0.05 -> 6.25 | Q8: =I8*3 -> 30 | R8: =IF(MIN(O8,P8)<Q8,MIN(O8,P8),Q8) -> 6.25 | S8: =IF(AND('Total income package'!$A$8=TRUE,OR(F8="Yes",G8="Yes",H8="Yes")),SUM(J8:N8)-R8,0) -> 1993.75
A9: 2000 | B9: =A9/12 -> 166.66667 | C9: ='Total income package'!$D$80 -> 0 | D9: =B9+C9 -> 166.66667 | E9: =D9/$K$2 -> 0.051706308 | F9: =IF(AND(B9<$N$2,SUM($C$2:$F$2)>0),"Yes","No") -> Yes | G9: =IF(B9<$M$2,"Yes","No") -> Yes | H9: =IF(OR('TANF-VIEW'!L13>0,'TANF-VIEW'!T13>0),"Yes","No") -> Yes | I9: =IF(B9>=$N$2,0,IF(E9>3.5,375*SUM($C$2:$H$2),IF(E9>3,325*SUM($C$2:$H$2),IF(E9>2.5,275*SUM($C$2:$H$2),IF(E9>2,225*SUM($C$2:$H$2),IF(E9>1.5,175*SUM($C$2:$H$2),IF(E9>1,125*SUM($C$2:$H$2),IF(E9>0,5*SUM($C$2:$H$2),0)))))))) -> 10 | J9: =(IF(B9>$N$2,0,VLOOKUP('Total income package'!$B$3,'Location specific data'!$A$3:$AO$135,33,FALSE))*$C$2)*20 -> 1400 | K9: =IF(B9>$N$2,0,VLOOKUP('Total income package'!$B$3,'Location specific data'!$A$3:$AO$135,34,FALSE))*$D$2*20 -> 0 | L9: =IF(B9>$N$2,0,VLOOKUP('Total income package'!$B$3,'Location specific data'!$A$3:$AO$135,35,FALSE))*$E$2*20 -> 0 | M9: =IF(B9>$N$2,0,VLOOKUP('Total income package'!$B$3,'Location specific data'!$A$3:$AO$135,36,FALSE))*$F$2*20 -> 0 | N9: =IF(B9>$N$2,0,VLOOKUP('Total income package'!$B$3,'Location specific data'!$A$3:$AO$135,37,FALSE))*($G$2+$H$2)*20 -> 600 | O9: =I9*SUM($C$2:$H$2) -> 20 | P9: =B9*0.05 -> 8.3333333 | Q9: =I9*3 -> 30 | R9: =IF(MIN(O9,P9)<Q9,MIN(O9,P9),Q9) -> 8.3333333 | S9: =IF(AND('Total income package'!$A$8=TRUE,OR(F9="Yes",G9="Yes",H9="Yes")),SUM(J9:N9)-R9,0) -> 1991.6667
A10: 2500 | B10: =A10/12 -> 208.33333 | C10: ='Total income package'!$D$80 -> 0 | D10: =B10+C10 -> 208.33333 | E10: =D10/$K$2 -> 0.064632885 | F10: =IF(AND(B10<$N$2,SUM($C$2:$F$2)>0),"Yes","No") -> Yes | G10: =IF(B10<$M$2,"Yes","No") -> Yes | H10: =IF(OR('TANF-VIEW'!L14>0,'TANF-VIEW'!T14>0),"Yes","No") -> Yes | I10: =IF(B10>=$N$2,0,IF(E10>3.5,375*SUM($C$2:$H$2),IF(E10>3,325*SUM($C$2:$H$2),IF(E10>2.5,275*SUM($C$2:$H$2),IF(E10>2,225*SUM($C$2:$H$2),IF(E10>1.5,175*SUM($C$2:$H$2),IF(E10>1,125*SUM($C$2:$H$2),IF(E10>0,5*SUM($C$2:$H$2),0)))))))) -> 10 | J10: =(IF(B10>$N$2,0,VLOOKUP('Total income package'!$B$3,'Location specific data'!$A$3:$AO$135,33,FALSE))*$C$2)*20 -> 1400 | K10: =IF(B10>$N$2,0,VLOOKUP('Total income package'!$B$3,'Location specific data'!$A$3:$AO$135,34,FALSE))*$D$2*20 -> 0 | L10: =IF(B10>$N$2,0,VLOOKUP('Total income package'!$B$3,'Location specific data'!$A$3:$AO$135,35,FALSE))*$E$2*20 -> 0 | M10: =IF(B10>$N$2,0,VLOOKUP('Total income package'!$B$3,'Location specific data'!$A$3:$AO$135,36,FALSE))*$F$2*20 -> 0 | N10: =IF(B10>$N$2,0,VLOOKUP('Total income package'!$B$3,'Location specific data'!$A$3:$AO$135,37,FALSE))*($G$2+$H$2)*20 -> 600 | O10: =I10*SUM($C$2:$H$2) -> 20 | P10: =B10*0.05 -> 10.416667 | Q10: =I10*3 -> 30 | R10: =IF(MIN(O10,P10)<Q10,MIN(O10,P10),Q10) -> 10.416667 | S10: =IF(AND('Total income package'!$A$8=TRUE,OR(F10="Yes",G10="Yes",H10="Yes")),SUM(J10:N10)-R10,0) -> 1989.5833
A11: 3000 | B11: =A11/12 -> 250 | C11: ='Total income package'!$D$80 -> 0 | D11: =B11+C11 -> 250 | E11: =D11/$K$2 -> 0.077559462 | F11: =IF(AND(B11<$N$2,SUM($C$2:$F$2)>0),"Yes","No") -> Yes | G11: =IF(B11<$M$2,"Yes","No") -> Yes | H11: =IF(OR('TANF-VIEW'!L15>0,'TANF-VIEW'!T15>0),"Yes","No") -> Yes | I11: =IF(B11>=$N$2,0,IF(E11>3.5,375*SUM($C$2:$H$2),IF(E11>3,325*SUM($C$2:$H$2),IF(E11>2.5,275*SUM($C$2:$H$2),IF(E11>2,225*SUM($C$2:$H$2),IF(E11>1.5,175*SUM($C$2:$H$2),IF(E11>1,125*SUM($C$2:$H$2),IF(E11>0,5*SUM($C$2:$H$2),0)))))))) -> 10 | J11: =(IF(B11>$N$2,0,VLOOKUP('Total income package'!$B$3,'Location specific data'!$A$3:$AO$135,33,FALSE))*$C$2)*20 -> 1400 | K11: =IF(B11>$N$2,0,VLOOKUP('Total income package'!$B$3,'Location specific data'!$A$3:$AO$135,34,FALSE))*$D$2*20 -> 0 | L11: =IF(B11>$N$2,0,VLOOKUP('Total income package'!$B$3,'Location specific data'!$A$3:$AO$135,35,FALSE))*$E$2*20 -> 0 | M11: =IF(B11>$N$2,0,VLOOKUP('Total income package'!$B$3,'Location specific data'!$A$3:$AO$135,36,FALSE))*$F$2*20 -> 0 | N11: =IF(B11>$N$2,0,VLOOKUP('Total income package'!$B$3,'Location specific data'!$A$3:$AO$135,37,FALSE))*($G$2+$H$2)*20 -> 600 | O11: =I11*SUM($C$2:$H$2) -> 20 | P11: =B11*0.05 -> 12.5 | Q11: =I11*3 -> 30 | R11: =IF(MIN(O11,P11)<Q11,MIN(O11,P11),Q11) -> 12.5 | S11: =IF(AND('Total income package'!$A$8=TRUE,OR(F11="Yes",G11="Yes",H11="Yes")),SUM(J11:N11)-R11,0) -> 1987.5
A12: 3500 | B12: =A12/12 -> 291.66667 | C12: ='Total income package'!$D$80 -> 0 | D12: =B12+C12 -> 291.66667 | E12: =D12/$K$2 -> 0.090486039 | F12: =IF(AND(B12<$N$2,SUM($C$2:$F$2)>0),"Yes","No") -> Yes | G12: =IF(B12<$M$2,"Yes","No") -> Yes | H12: =IF(OR('TANF-VIEW'!L16>0,'TANF-VIEW'!T16>0),"Yes","No") -> Yes | I12: =IF(B12>=$N$2,0,IF(E12>3.5,375*SUM($C$2:$H$2),IF(E12>3,325*SUM($C$2:$H$2),IF(E12>2.5,275*SUM($C$2:$H$2),IF(E12>2,225*SUM($C$2:$H$2),IF(E12>1.5,175*SUM($C$2:$H$2),IF(E12>1,125*SUM($C$2:$H$2),IF(E12>0,5*SUM($C$2:$H$2),0)))))))) -> 10 | J12: =(IF(B12>$N$2,0,VLOOKUP('Total income package'!$B$3,'Location specific data'!$A$3:$AO$135,33,FALSE))*$C$2)*20 -> 1400 | K12: =IF(B12>$N$2,0,VLOOKUP('Total income package'!$B$3,'Location specific data'!$A$3:$AO$135,34,FALSE))*$D$2*20 -> 0 | L12: =IF(B12>$N$2,0,VLOOKUP('Total income package'!$B$3,'Location specific data'!$A$3:$AO$135,35,FALSE))*$E$2*20 -> 0 | M12: =IF(B12>$N$2,0,VLOOKUP('Total income package'!$B$3,'Location specific data'!$A$3:$AO$135,36,FALSE))*$F$2*20 -> 0 | N12: =IF(B12>$N$2,0,VLOOKUP('Total income package'!$B$3,'Location specific data'!$A$3:$AO$135,37,FALSE))*($G$2+$H$2)*20 -> 600 | O12: =I12*SUM($C$2:$H$2) -> 20 | P12: =B12*0.05 -> 14.583333 | Q12: =I12*3 -> 30 | R12: =IF(MIN(O12,P12)<Q12,MIN(O12,P12),Q12) -> 14.583333 | S12: =IF(AND('Total income package'!$A$8=TRUE,OR(F12="Yes",G12="Yes",H12="Yes")),SUM(J12:N12)-R12,0) -> 1985.4167
A13: 4000 | B13: =A13/12 -> 333.33333 | C13: ='Total income package'!$D$80 -> 0 | D13: =B13+C13 -> 333.33333 | E13: =D13/$K$2 -> 0.10341262 | F13: =IF(AND(B13<$N$2,SUM($C$2:$F$2)>0),"Yes","No") -> Yes | G13: =IF(B13<$M$2,"Yes","No") -> Yes | H13: =IF(OR('TANF-VIEW'!L17>0,'TANF-VIEW'!T17>0),"Yes","No") -> Yes | I13: =IF(B13>=$N$2,0,IF(E13>3.5,375*SUM($C$2:$H$2),IF(E13>3,325*SUM($C$2:$H$2),IF(E13>2.5,275*SUM($C$2:$H$2),IF(E13>2,225*SUM($C$2:$H$2),IF(E13>1.5,175*SUM($C$2:$H$2),IF(E13>1,125*SUM($C$2:$H$2),IF(E13>0,5*SUM($C$2:$H$2),0)))))))) -> 10 | J13: =(IF(B13>$N$2,0,VLOOKUP('Total income package'!$B$3,'Location specific data'!$A$3:$AO$135,33,FALSE))*$C$2)*20 -> 1400 | K13: =IF(B13>$N$2,0,VLOOKUP('Total income package'!$B$3,'Location specific data'!$A$3:$AO$135,34,FALSE))*$D$2*20 -> 0 | L13: =IF(B13>$N$2,0,VLOOKUP('Total income package'!$B$3,'Location specific data'!$A$3:$AO$135,35,FALSE))*$E$2*20 -> 0 | M13: =IF(B13>$N$2,0,VLOOKUP('Total income package'!$B$3,'Location specific data'!$A$3:$AO$135,36,FALSE))*$F$2*20 -> 0 | N13: =IF(B13>$N$2,0,VLOOKUP('Total income package'!$B$3,'Location specific data'!$A$3:$AO$135,37,FALSE))*($G$2+$H$2)*20 -> 600 | O13: =I13*SUM($C$2:$H$2) -> 20 | P13: =B13*0.05 -> 16.666667 | Q13: =I13*3 -> 30 | R13: =IF(MIN(O13,P13)<Q13,MIN(O13,P13),Q13) -> 16.666667 | S13: =IF(AND('Total income package'!$A$8=TRUE,OR(F13="Yes",G13="Yes",H13="Yes")),SUM(J13:N13)-R13,0) -> 1983.3333
A14: 4500 | B14: =A14/12 -> 375 | C14: ='Total income package'!$D$80 -> 0 | D14: =B14+C14 -> 375 | E14: =D14/$K$2 -> 0.11633919 | F14: =IF(AND(B14<$N$2,SUM($C$2:$F$2)>0),"Yes","No") -> Yes | G14: =IF(B14<$M$2,"Yes","No") -> Yes | H14: =IF(OR('TANF-VIEW'!L18>0,'TANF-VIEW'!T18>0),"Yes","No") -> Yes | I14: =IF(B14>=$N$2,0,IF(E14>3.5,375*SUM($C$2:$H$2),IF(E14>3,325*SUM($C$2:$H$2),IF(E14>2.5,275*SUM($C$2:$H$2),IF(E14>2,225*SUM($C$2:$H$2),IF(E14>1.5,175*SUM($C$2:$H$2),IF(E14>1,125*SUM($C$2:$H$2),IF(E14>0,5*SUM($C$2:$H$2),0)))))))) -> 10 | J14: =(IF(B14>$N$2,0,VLOOKUP('Total income package'!$B$3,'Location specific data'!$A$3:$AO$135,33,FALSE))*$C$2)*20 -> 1400 | K14: =IF(B14>$N$2,0,VLOOKUP('Total income package'!$B$3,'Location specific data'!$A$3:$AO$135,34,FALSE))*$D$2*20 -> 0 | L14: =IF(B14>$N$2,0,VLOOKUP('Total income package'!$B$3,'Location specific data'!$A$3:$AO$135,35,FALSE))*$E$2*20 -> 0 | M14: =IF(B14>$N$2,0,VLOOKUP('Total income package'!$B$3,'Location specific data'!$A$3:$AO$135,36,FALSE))*$F$2*20 -> 0 | N14: =IF(B14>$N$2,0,VLOOKUP('Total income package'!$B$3,'Location specific data'!$A$3:$AO$135,37,FALSE))*($G$2+$H$2)*20 -> 600 | O14: =I14*SUM($C$2:$H$2) -> 20 | P14: =B14*0.05 -> 18.75 | Q14: =I14*3 -> 30 | R14: =IF(MIN(O14,P14)<Q14,MIN(O14,P14),Q14) -> 18.75 | S14: =IF(AND('Total income package'!$A$8=TRUE,OR(F14="Yes",G14="Yes",H14="Yes")),SUM(J14:N14)-R14,0) -> 1981.25
A15: 5000 | B15: =A15/12 -> 416.66667 | C15: ='Total income package'!$D$80 -> 0 | D15: =B15+C15 -> 416.66667 | E15: =D15/$K$2 -> 0.12926577 | F15: =IF(AND(B15<$N$2,SUM($C$2:$F$2)>0),"Yes","No") -> Yes | G15: =IF(B15<$M$2,"Yes","No") -> Yes | H15: =IF(OR('TANF-VIEW'!L19>0,'TANF-VIEW'!T19>0),"Yes","No") -> Yes | I15: =IF(B15>=$N$2,0,IF(E15>3.5,375*SUM($C$2:$H$2),IF(E15>3,325*SUM($C$2:$H$2),IF(E15>2.5,275*SUM($C$2:$H$2),IF(E15>2,225*SUM($C$2:$H$2),IF(E15>1.5,175*SUM($C$2:$H$2),IF(E15>1,125*SUM($C$2:$H$2),IF(E15>0,5*SUM($C$2:$H$2),0)))))))) -> 10 | J15: =(IF(B15>$N$2,0,VLOOKUP('Total income package'!$B$3,'Location specific data'!$A$3:$AO$135,33,FALSE))*$C$2)*20 -> 1400 | K15: =IF(B15>$N$2,0,VLOOKUP('Total income package'!$B$3,'Location specific data'!$A$3:$AO$135,34,FALSE))*$D$2*20 -> 0 | L15: =IF(B15>$N$2,0,VLOOKUP('Total income package'!$B$3,'Location specific data'!$A$3:$AO$135,35,FALSE))*$E$2*20 -> 0 | M15: =IF(B15>$N$2,0,VLOOKUP('Total income package'!$B$3,'Location specific data'!$A$3:$AO$135,36,FALSE))*$F$2*20 -> 0 | N15: =IF(B15>$N$2,0,VLOOKUP('Total income package'!$B$3,'Location specific data'!$A$3:$AO$135,37,FALSE))*($G$2+$H$2)*20 -> 600 | O15: =I15*SUM($C$2:$H$2) -> 20 | P15: =B15*0.05 -> 20.833333 | Q15: =I15*3 -> 30 | R15: =IF(MIN(O15,P15)<Q15,MIN(O15,P15),Q15) -> 20 | S15: =IF(AND('Total income package'!$A$8=TRUE,OR(F15="Yes",G15="Yes",H15="Yes")),SUM(J15:N15)-R15,0) -> 1980
A16: 5500 | B16: =A16/12 -> 458.33333 | C16: ='Total income package'!$D$80 -> 0 | D16: =B16+C16 -> 458.33333 | E16: =D16/$K$2 -> 0.14219235 | F16: =IF(AND(B16<$N$2,SUM($C$2:$F$2)>0),"Yes","No") -> Yes | G16: =IF(B16<$M$2,"Yes","No") -> Yes | H16: =IF(OR('TANF-VIEW'!L20>0,'TANF-VIEW'!T20>0),"Yes","No") -> Yes | I16: =IF(B16>=$N$2,0,IF(E16>3.5,375*SUM($C$2:$H$2),IF(E16>3,325*SUM($C$2:$H$2),IF(E16>2.5,275*SUM($C$2:$H$2),IF(E16>2,225*SUM($C$2:$H$2),IF(E16>1.5,175*SUM($C$2:$H$2),IF(E16>1,125*SUM($C$2:$H$2),IF(E16>0,5*SUM($C$2:$H$2),0)))))))) -> 10 | J16: =(IF(B16>$N$2,0,VLOOKUP('Total income package'!$B$3,'Location specific data'!$A$3:$AO$135,33,FALSE))*$C$2)*20 -> 1400 | K16: =IF(B16>$N$2,0,VLOOKUP('Total income package'!$B$3,'Location specific data'!$A$3:$AO$135,34,FALSE))*$D$2*20 -> 0 | L16: =IF(B16>$N$2,0,VLOOKUP('Total income package'!$B$3,'Location specific data'!$A$3:$AO$135,35,FALSE))*$E$2*20 -> 0 | M16: =IF(B16>$N$2,0,VLOOKUP('Total income package'!$B$3,'Location specific data'!$A$3:$AO$135,36,FALSE))*$F$2*20 -> 0 | N16: =IF(B16>$N$2,0,VLOOKUP('Total income package'!$B$3,'Location specific data'!$A$3:$AO$135,37,FALSE))*($G$2+$H$2)*20 -> 600 | O16: =I16*SUM($C$2:$H$2) -> 20 | P16: =B16*0.05 -> 22.916667 | Q16: =I16*3 -> 30 | R16: =IF(MIN(O16,P16)<Q16,MIN(O16,P16),Q16) -> 20 | S16: =IF(AND('Total income package'!$A$8=TRUE,OR(F16="Yes",G16="Yes",H16="Yes")),SUM(J16:N16)-R16,0) -> 1980
... A204: 99500 | B204: =A204/12 -> 8291.6667 | C204: ='Total income package'!$D$80 -> 0 | D204: =B204+C204 -> 8291.6667 | E204: =D204/$K$2 -> 2.5723888 | F204: =IF(AND(B204<$N$2,SUM($C$2:$F$2)>0),"Yes","No") -> Yes | G204: =IF(B204<$M$2,"Yes","No") -> No | H204: =IF(OR('TANF-VIEW'!L208>0,'TANF-VIEW'!T208>0),"Yes","No") -> No | I204: =IF(B204>=$N$2,0,IF(E204>3.5,375*SUM($C$2:$H$2),IF(E204>3,325*SUM($C$2:$H$2),IF(E204>2.5,275*SUM($C$2:$H$2),IF(E204>2,225*SUM($C$2:$H$2),IF(E204>1.5,175*SUM($C$2:$H$2),IF(E204>1,125*SUM($C$2:$H$2),IF(E204>0,5*SUM($C$2:$H$2),0)))))))) -> 550 | J204: =(IF(B204>$N$2,0,VLOOKUP('Total income package'!$B$3,'Location specific data'!$A$3:$AO$135,33,FALSE))*$C$2)*20 -> 1400 | K204: =IF(B204>$N$2,0,VLOOKUP('Total income package'!$B$3,'Location specific data'!$A$3:$AO$135,34,FALSE))*$D$2*20 -> 0 | L204: =IF(B204>$N$2,0,VLOOKUP('Total income package'!$B$3,'Location specific data'!$A$3:$AO$135,35,FALSE))*$E$2*20 -> 0 | M204: =IF(B204>$N$2,0,VLOOKUP('Total income package'!$B$3,'Location specific data'!$A$3:$AO$135,36,FALSE))*$F$2*20 -> 0 | N204: =IF(B204>$N$2,0,VLOOKUP('Total income package'!$B$3,'Location specific data'!$A$3:$AO$135,37,FALSE))*($G$2+$H$2)*20 -> 600 | O204: =I204*SUM($C$2:$H$2) -> 1100 | P204: =B204*0.05 -> 414.58333 | Q204: =I204*3 -> 1650 | R204: =IF(MIN(O204,P204)<Q204,MIN(O204,P204),Q204) -> 414.58333 | S204: =IF(AND('Total income package'!$A$8=TRUE,OR(F204="Yes",G204="Yes",H204="Yes")),SUM(J204:N204)-R204,0) -> 1585.4167
A205: 100000 | B205: =A205/12 -> 8333.3333 | C205: ='Total income package'!$D$80 -> 0 | D205: =B205+C205 -> 8333.3333 | E205: =D205/$K$2 -> 2.5853154 | F205: =IF(AND(B205<$N$2,SUM($C$2:$F$2)>0),"Yes","No") -> Yes | G205: =IF(B205<$M$2,"Yes","No") -> No | H205: =IF(OR('TANF-VIEW'!L209>0,'TANF-VIEW'!T209>0),"Yes","No") -> No | I205: =IF(B205>=$N$2,0,IF(E205>3.5,375*SUM($C$2:$H$2),IF(E205>3,325*SUM($C$2:$H$2),IF(E205>2.5,275*SUM($C$2:$H$2),IF(E205>2,225*SUM($C$2:$H$2),IF(E205>1.5,175*SUM($C$2:$H$2),IF(E205>1,125*SUM($C$2:$H$2),IF(E205>0,5*SUM($C$2:$H$2),0)))))))) -> 550 | J205: =(IF(B205>$N$2,0,VLOOKUP('Total income package'!$B$3,'Location specific data'!$A$3:$AO$135,33,FALSE))*$C$2)*20 -> 1400 | K205: =IF(B205>$N$2,0,VLOOKUP('Total income package'!$B$3,'Location specific data'!$A$3:$AO$135,34,FALSE))*$D$2*20 -> 0 | L205: =IF(B205>$N$2,0,VLOOKUP('Total income package'!$B$3,'Location specific data'!$A$3:$AO$135,35,FALSE))*$E$2*20 -> 0 | M205: =IF(B205>$N$2,0,VLOOKUP('Total income package'!$B$3,'Location specific data'!$A$3:$AO$135,36,FALSE))*$F$2*20 -> 0 | N205: =IF(B205>$N$2,0,VLOOKUP('Total income package'!$B$3,'Location specific data'!$A$3:$AO$135,37,FALSE))*($G$2+$H$2)*20 -> 600 | O205: =I205*SUM($C$2:$H$2) -> 1100 | P205: =B205*0.07 -> 583.33333 | Q205: =I205*3 -> 1650 | R205: =IF(MIN(O205,P205)<Q205,MIN(O205,P205),Q205) -> 583.33333 | S205: =IF(AND('Total income package'!$A$8=TRUE,OR(F205="Yes",G205="Yes",H205="Yes")),SUM(J205:N205)-R205,0) -> 1416.6667
A207: Exact income-start
B208: ='Total income package'!$B$90 -> 1423 | C208: ='Total income package'!$D$80 -> 0 | D208: =B208+C208 -> 1423 | E208: =D208/$K$2 -> 0.44146846 | F208: =IF(AND(B208<$N$2,SUM($C$2:$F$2)>0),"Yes","No") -> Yes | G208: =IF(B208<$M$2,"Yes","No") -> Yes | H208: =IF(OR('TANF-VIEW'!L212>0,'TANF-VIEW'!T212>0),"Yes","No") -> No | I208: =IF(B208>=$N$2,0,IF(E208>3.5,375*SUM($C$2:$H$2),IF(E208>3,325*SUM($C$2:$H$2),IF(E208>2.5,275*SUM($C$2:$H$2),IF(E208>2,225*SUM($C$2:$H$2),IF(E208>1.5,175*SUM($C$2:$H$2),IF(E208>1,125*SUM($C$2:$H$2),IF(E208>0,5*SUM($C$2:$H$2),0)))))))) -> 10 | J208: =(IF(B208>$N$2,0,VLOOKUP('Total income package'!$B$3,'Location specific data'!$A$3:$AO$135,33,FALSE))*$C$2)*20 -> 1400 | K208: =IF(B208>$N$2,0,VLOOKUP('Total income package'!$B$3,'Location specific data'!$A$3:$AO$135,34,FALSE))*$D$2*20 -> 0 | L208: =IF(B208>$N$2,0,VLOOKUP('Total income package'!$B$3,'Location specific data'!$A$3:$AO$135,35,FALSE))*$E$2*20 -> 0 | M208: =IF(B208>$N$2,0,VLOOKUP('Total income package'!$B$3,'Location specific data'!$A$3:$AO$135,36,FALSE))*$F$2*20 -> 0 | N208: =IF(B208>$N$2,0,VLOOKUP('Total income package'!$B$3,'Location specific data'!$A$3:$AO$135,37,FALSE))*($G$2+$H$2)*20 -> 600 | O208: =I208*SUM($C$2:$H$2) -> 20 | P208: =B208*0.05 -> 71.15 | Q208: =I208*3 -> 30 | R208: =IF(MIN(O208,P208)<Q208,MIN(O208,P208),Q208) -> 20 | S208: =IF(AND('Total income package'!$A$8=TRUE,OR(F208="Yes",G208="Yes",H208="Yes")),SUM(J208:N208)-R208,0) -> 1980
A209: Exact income-new
B210: ='Total income package'!$B$91 -> 3000 | C210: ='Total income package'!$D$80 -> 0 | D210: =B210+C210 -> 3000 | E210: =D210/$K$2 -> 0.93071355 | F210: =IF(AND(B210<$N$2,SUM($C$2:$F$2)>0),"Yes","No") -> Yes | G210: =IF(B210<$M$2,"Yes","No") -> Yes | H210: =IF(OR('TANF-VIEW'!L214>0,'TANF-VIEW'!T214>0),"Yes","No") -> No | I210: =IF(B210>=$N$2,0,IF(E210>3.5,375*SUM($C$2:$H$2),IF(E210>3,325*SUM($C$2:$H$2),IF(E210>2.5,275*SUM($C$2:$H$2),IF(E210>2,225*SUM($C$2:$H$2),IF(E210>1.5,175*SUM($C$2:$H$2),IF(E210>1,125*SUM($C$2:$H$2),IF(E210>0,5*SUM($C$2:$H$2),0)))))))) -> 10 | J210: =(IF(B210>$N$2,0,VLOOKUP('Total income package'!$B$3,'Location specific data'!$A$3:$AO$135,33,FALSE))*$C$2)*20 -> 1400 | K210: =IF(B210>$N$2,0,VLOOKUP('Total income package'!$B$3,'Location specific data'!$A$3:$AO$135,34,FALSE))*$D$2*20 -> 0 | L210: =IF(B210>$N$2,0,VLOOKUP('Total income package'!$B$3,'Location specific data'!$A$3:$AO$135,35,FALSE))*$E$2*20 -> 0 | M210: =IF(B210>$N$2,0,VLOOKUP('Total income package'!$B$3,'Location specific data'!$A$3:$AO$135,36,FALSE))*$F$2*20 -> 0 | N210: =IF(B210>$N$2,0,VLOOKUP('Total income package'!$B$3,'Location specific data'!$A$3:$AO$135,37,FALSE))*($G$2+$H$2)*20 -> 600 | O210: =I210*SUM($C$2:$H$2) -> 20 | P210: =B210*0.05 -> 150 | Q210: =I210*3 -> 30 | R210: =IF(MIN(O210,P210)<Q210,MIN(O210,P210),Q210) -> 20 | S210: =IF(AND('Total income package'!$A$8=TRUE,OR(F210="Yes",G210="Yes",H210="Yes")),SUM(J210:N210)-R210,0) -> 1980

Sheet EITC
A1: Location | B1: Number in Household | C1: Number adults | D1: Number of children | E1: Filing status | F1: AGI must be below | G1: Max credit amount | H1: Phase in | I1: Phase out | J1: Max credit starts at | K1: Phase-out starts at | M1: EITC does not count SSI/SSDI as earned income
A2: ='Total income package'!B3 -> Buckingham | B2: ='Total income package'!B32 -> 5 | C2: ='Total income package'!B30 -> 3 | D2: ='Total income package'!B31 -> 2 | E2: ='Total income package'!B72 -> Married filing jointly | F2: =IF($E$2="Married filing jointly",VLOOKUP($D$2,'EITC Rates'!$A$17:$G$24,2,FALSE),VLOOKUP($D$2,'EITC Rates'!$A$6:$G$13,2,FALSE)) -> 64430 | G2: =IF($E$2="Married filing jointly",VLOOKUP($D$2,'EITC Rates'!$A$17:$G$24,3,FALSE),VLOOKUP($D$2,'EITC Rates'!$A$6:$G$13,3,FALSE)) -> 7316 | H2: =IF($E$2="Married filing jointly",VLOOKUP($D$2,'EITC Rates'!$A$17:$G$24,4,FALSE),VLOOKUP($D$2,'EITC Rates'!$A$6:$G$13,4,FALSE)) -> 0.4 | I2: =IF($E$2="Married filing jointly",VLOOKUP($D$2,'EITC Rates'!$A$17:$G$24,5,FALSE),VLOOKUP($D$2,'EITC Rates'!$A$6:$G$13,5,FALSE)) -> 0.2106 | J2: =IF($E$2="Married filing jointly",VLOOKUP($D$2,'EITC Rates'!$A$17:$G$24,6,FALSE),VLOOKUP($D$2,'EITC Rates'!$A$6:$G$13,6,FALSE)) -> 18290 | K2: =IF($E$2="Married filing jointly",VLOOKUP($D$2,'EITC Rates'!$A$17:$G$24,7,FALSE),VLOOKUP($D$2,'EITC Rates'!$A$6:$G$13,7,FALSE)) -> 31160
A4: Annual earned income | B4: Monthly earned income | C4: Calculated Federal EITC w/ 2026 rates *Off by between $5- $10 from P596 | D4: VA EITC 20% of Federal EITC | E4: Combined Federal & VA EITC (Annual) | G4: Beginning with tax year 2025 (returns due May 2026), the refundable Virginia Earned Income Tax Credit will increase to 20% of your federal Earned Income Tax Credit.
A5: 0 | B5: =A5/12 -> 0 | C5: 0 | D5: =C5*0.2 -> 0 | E5: =IF('Total income package'!$A$10=TRUE,SUM(EITC!C5:D5),0) -> 0
A6: 500 | B6: =A6/12 -> 41.666667 | C6: =MAX(0,IF(A6>$F$2,0,IF(AND(A6<$F$2,A6>=$K$2),$G$2-((A6-$K$2-1)*$I$2),IF(AND(A6<$K$2,A6>=$J$2),$G$2,IF(A6<$J$2,A6*$H$2,0))))) -> 200 | D6: =C6*0.2 -> 40 | E6: =IF('Total income package'!$A$10=TRUE,SUM(EITC!C6:D6),0) -> 240
A7: 1000 | B7: =A7/12 -> 83.333333 | C7: =MAX(0,IF(A7>$F$2,0,IF(AND(A7<$F$2,A7>=$K$2),$G$2-((A7-$K$2-1)*$I$2),IF(AND(A7<$K$2,A7>=$J$2),$G$2,IF(A7<$J$2,A7*$H$2,0))))) -> 400 | D7: =C7*0.2 -> 80 | E7: =IF('Total income package'!$A$10=TRUE,SUM(EITC!C7:D7),0) -> 480
A8: 1500 | B8: =A8/12 -> 125 | C8: =MAX(0,IF(A8>$F$2,0,IF(AND(A8<$F$2,A8>=$K$2),$G$2-((A8-$K$2-1)*$I$2),IF(AND(A8<$K$2,A8>=$J$2),$G$2,IF(A8<$J$2,A8*$H$2,0))))) -> 600 | D8: =C8*0.2 -> 120 | E8: =IF('Total income package'!$A$10=TRUE,SUM(EITC!C8:D8),0) -> 720
A9: 2000 | B9: =A9/12 -> 166.66667 | C9: =MAX(0,IF(A9>$F$2,0,IF(AND(A9<$F$2,A9>=$K$2),$G$2-((A9-$K$2-1)*$I$2),IF(AND(A9<$K$2,A9>=$J$2),$G$2,IF(A9<$J$2,A9*$H$2,0))))) -> 800 | D9: =C9*0.2 -> 160 | E9: =IF('Total income package'!$A$10=TRUE,SUM(EITC!C9:D9),0) -> 960
A10: 2500 | B10: =A10/12 -> 208.33333 | C10: =MAX(0,IF(A10>$F$2,0,IF(AND(A10<$F$2,A10>=$K$2),$G$2-((A10-$K$2-1)*$I$2),IF(AND(A10<$K$2,A10>=$J$2),$G$2,IF(A10<$J$2,A10*$H$2,0))))) -> 1000 | D10: =C10*0.2 -> 200 | E10: =IF('Total income package'!$A$10=TRUE,SUM(EITC!C10:D10),0) -> 1200
A11: 3000 | B11: =A11/12 -> 250 | C11: =MAX(0,IF(A11>$F$2,0,IF(AND(A11<$F$2,A11>=$K$2),$G$2-((A11-$K$2-1)*$I$2),IF(AND(A11<$K$2,A11>=$J$2),$G$2,IF(A11<$J$2,A11*$H$2,0))))) -> 1200 | D11: =C11*0.2 -> 240 | E11: =IF('Total income package'!$A$10=TRUE,SUM(EITC!C11:D11),0) -> 1440
A12: 3500 | B12: =A12/12 -> 291.66667 | C12: =MAX(0,IF(A12>$F$2,0,IF(AND(A12<$F$2,A12>=$K$2),$G$2-((A12-$K$2-1)*$I$2),IF(AND(A12<$K$2,A12>=$J$2),$G$2,IF(A12<$J$2,A12*$H$2,0))))) -> 1400 | D12: =C12*0.2 -> 280 | E12: =IF('Total income package'!$A$10=TRUE,SUM(EITC!C12:D12),0) -> 1680
A13: 4000 | B13: =A13/12 -> 333.33333 | C13: =MAX(0,IF(A13>$F$2,0,IF(AND(A13<$F$2,A13>=$K$2),$G$2-((A13-$K$2-1)*$I$2),IF(AND(A13<$K$2,A13>=$J$2),$G$2,IF(A13<$J$2,A13*$H$2,0))))) -> 1600 | D13: =C13*0.2 -> 320 | E13: =IF('Total income package'!$A$10=TRUE,SUM(EITC!C13:D13),0) -> 1920
A14: 4500 | B14: =A14/12 -> 375 | C14: =MAX(0,IF(A14>$F$2,0,IF(AND(A14<$F$2,A14>=$K$2),$G$2-((A14-$K$2-1)*$I$2),IF(AND(A14<$K$2,A14>=$J$2),$G$2,IF(A14<$J$2,A14*$H$2,0))))) -> 1800 | D14: =C14*0.2 -> 360 | E14: =IF('Total income package'!$A$10=TRUE,SUM(EITC!C14:D14),0) -> 2160
A15: 5000 | B15: =A15/12 -> 416.66667 | C15: =MAX(0,IF(A15>$F$2,0,IF(AND(A15<$F$2,A15>=$K$2),$G$2-((A15-$K$2-1)*$I$2),IF(AND(A15<$K$2,A15>=$J$2),$G$2,IF(A15<$J$2,A15*$H$2,0))))) -> 2000 | D15: =C15*0.2 -> 400 | E15: =IF('Total income package'!$A$10=TRUE,SUM(EITC!C15:D15),0) -> 2400
A16: 5500 | B16: =A16/12 -> 458.33333 | C16: =MAX(0,IF(A16>$F$2,0,IF(AND(A16<$F$2,A16>=$K$2),$G$2-((A16-$K$2-1)*$I$2),IF(AND(A16<$K$2,A16>=$J$2),$G$2,IF(A16<$J$2,A16*$H$2,0))))) -> 2200 | D16: =C16*0.2 -> 440 | E16: =IF('Total income package'!$A$10=TRUE,SUM(EITC!C16:D16),0) -> 2640
A17: 6000 | B17: =A17/12 -> 500 | C17: =MAX(0,IF(A17>$F$2,0,IF(AND(A17<$F$2,A17>=$K$2),$G$2-((A17-$K$2-1)*$I$2),IF(AND(A17<$K$2,A17>=$J$2),$G$2,IF(A17<$J$2,A17*$H$2,0))))) -> 2400 | D17: =C17*0.2 -> 480 | E17: =IF('Total income package'!$A$10=TRUE,SUM(EITC!C17:D17),0) -> 2880
... A205: 100000 | B205: =A205/12 -> 8333.3333 | C205: =MAX(0,IF(A205>$F$2,0,IF(AND(A205<$F$2,A205>=$K$2),$G$2-((A205-$K$2-1)*$I$2),IF(AND(A205<$K$2,A205>=$J$2),$G$2,IF(A205<$J$2,A205*$H$2,0))))) -> 0 | D205: =C205*0.2 -> 0 | E205: =IF('Total income package'!$A$10=TRUE,SUM(EITC!C205:D205),0) -> 0
A207: Exact income-start | E207: Fed & VA EITC | K207: =1770/12 -> 147.5
A208: =B208*12 -> 17076 | B208: ='Total income package'!$B$90 -> 1423 | C208: =MAX(0,IF(A208>$F$2,0,IF(AND(A208<$F$2,A208>=$K$2),$G$2-((A208-$K$2-1)*$I$2),IF(AND(A208<$K$2,A208>=$J$2),$G$2,IF(A208<$J$2,A208*$H$2,0))))) -> 6830.4 | D208: =C208*0.15 -> 1024.56 | E208: =IF('Total income package'!$A$10=TRUE,C208+D208,0) -> 7854.96 | G208: =C208/12 -> 569.2 | H208: =E208/12 -> 654.58
A209: Exact income-new
A210: =B210*12 -> 36000 | B210: ='Total income package'!$B$91 -> 3000 | C210: =MAX(0,IF(A210>$F$2,0,IF(AND(A210<$F$2,A210>=$K$2),$G$2-((A210-$K$2-1)*$I$2),IF(AND(A210<$K$2,A210>=$J$2),$G$2,IF(A210<$J$2,A210*$H$2,0))))) -> 6296.9066 | D210: =C210*0.15 -> 944.53599 | E210: =IF('Total income package'!$A$10=TRUE,C210+D210,0) -> 7241.4426

Sheet Health insurance subsidy 
A1: Location | B1: Number in Household | C1: Number of adults | D1: Number of children | F1: =K2*1.38 -> 4448.2 | M1: Bottom | N1: Top | O1: Initial % | P1: Final %
A2: ='Total income package'!B3 -> Buckingham | B2: ='Total income package'!B32 -> 5 | C2: ='Total income package'!B30 -> 3 | D2: ='Total income package'!B31 -> 2 | J2: FPL 2024 Monthly | K2: =VLOOKUP(B2,'Program specific data'!A6:D13,3,FALSE) -> 3223.3333 | L2: <150 FPL | M2: 0 | N2: =K2*1.49 -> 4802.7667 | O2: 0 | P2: 0
A3: Age of adult(s): | C3: Cost of SLCSP | E3: (from PRD Technical Manual) | L3: 150-199 | M3: =K2*1.5 -> 4835 | N3: =K2*1.99 -> 6414.4333 | O3: 0 | P3: 0.02
A4: Adult 1 | B4: ='Total income package'!B37 -> 34 | C4: =IFERROR(VLOOKUP($A$2,'SLCSP premiums'!$A$4:$AV$137,HLOOKUP(B4,'SLCSP premiums'!$B$2:$AV$3,2,FALSE),FALSE),0) -> 469 | E4: Formula used= Individual contribution to premium = | L4: 200-249 | M4: =K2*2 -> 6446.6667 | N4: =K2*2.49 -> 8026.1 | O4: 0.02 | P4: 0.04
A5: Adult 2 | B5: ='Total income package'!B38 -> 28 | C5: =IFERROR(VLOOKUP($A$2,'SLCSP premiums'!$A$4:$AV$137,HLOOKUP(B5,'SLCSP premiums'!$B$2:$AV$3,2,FALSE),FALSE),0) -> 420 | E5: MAGI * (𝐼𝑛𝑖𝑡𝑖𝑎𝑙 % +(𝑀𝐴𝐺𝐼−𝑀𝑎𝑥 𝑝𝑟𝑒𝑣𝑖𝑜𝑢𝑠 𝐹𝑃𝐿 𝑡𝑜𝑝)∗ | L5: 250-299 | M5: =K2*2.5 -> 8058.3333 | N5: =K2*2.99 -> 9637.7667 | O5: 0.04 | P5: 0.06
A6: Adult 3 | B6: ='Total income package'!B39 -> 80 | C6: =IFERROR(VLOOKUP($A$2,'SLCSP premiums'!$A$4:$AV$137,HLOOKUP(B6,'SLCSP premiums'!$B$2:$AV$3,2,FALSE),FALSE),0) -> 0 | L6: 300-399 | M6: =K2*3 -> 9670 | N6: =K2*3.99 -> 12861.1 | O6: 0.06 | P6: 0.085
A7: Adult 4 | B7: ='Total income package'!B40 -> 0 | C7: =IFERROR(VLOOKUP($A$2,'SLCSP premiums'!$A$4:$AV$137,HLOOKUP(B7,'SLCSP premiums'!$B$2:$AV$3,2,FALSE),FALSE),0) -> 0 | L7: 400+ | M7: =K2*4 -> 12893.333 | N7: =500000/12 -> 41666.667 | O7: 0.085 | P7: 0.085
A8: Adult 5 | B8: ='Total income package'!B41 -> 0 | C8: =IFERROR(VLOOKUP($A$2,'SLCSP premiums'!$A$4:$AV$137,HLOOKUP(B8,'SLCSP premiums'!$B$2:$AV$3,2,FALSE),FALSE),0) -> 0
A9: Adult 6 | B9: ='Total income package'!B42 -> 0 | C9: =IFERROR(VLOOKUP($A$2,'SLCSP premiums'!$A$4:$AV$137,HLOOKUP(B9,'SLCSP premiums'!$B$2:$AV$3,2,FALSE),FALSE),0) -> 0
A10: Adult 7 | B10: ='Total income package'!B43 -> 0 | C10: =IFERROR(VLOOKUP($A$2,'SLCSP premiums'!$A$4:$AV$137,HLOOKUP(B10,'SLCSP premiums'!$B$2:$AV$3,2,FALSE),FALSE),0) -> 0
A11: Adult 8 | B11: ='Total income package'!B44 -> 0 | C11: =IFERROR(VLOOKUP($A$2,'SLCSP premiums'!$A$4:$AV$137,HLOOKUP(B11,'SLCSP premiums'!$B$2:$AV$3,2,FALSE),FALSE),0) -> 0
A12: SLCSP-adults | C12: =SUM(C4:C11) -> 889
A13: # Children | B13: =D2 -> 2 | C13: =IFERROR(VLOOKUP($A$2,'SLCSP premiums'!A4:BE137,HLOOKUP(B13,'SLCSP premiums'!$B$2:$BE$3,2,FALSE),FALSE),0) -> 375
A14: NOTE: Medicaid calculated from 2024 FPL percentage-subsidies calculated from 2024 FPL for 2025 plan year.
D15: 2024 figures used (from https://www.healthcare.gov/glossary/federal-poverty-level-fpl/) | K15: Adult only until children no longer eligible for MA
A16: Annual earned income | B16: Monthly | C16: 0.0839 | D16: % FPL | E16: Income %-initial | F16: Income%-final | G16: Bottom income of FPL range | H16: Top income of FPL range | I16: Top income previous FPL | J16: Calculated individual contribution to premium | K16: SLCSP (from https://enroll.marketplace.virginia.gov/hix/preeligibility#/) | L16: Value of Marketplace subsidy (0 if eligible for Medicaid) | M16: Figures from https://enroll.marketplace.virginia.gov to check | N16: Annual Value Marketplace subsidies | O16: Adult eligible for MA? | P16: Children eligible MA?
A17: 0 | B17: =A17/12 -> 0 | C17: =B17*0.0839 -> 0 | D17: =B17/$K$2 -> 0 | E17: =IF($D$17>3.99,0.085,IF($D$17>2.99,0.06,IF($D$17>1.99,0.02,IF($D$17>1.49,0,0)))) -> 0 | F17: =IF(D17>3.99,0.085,IF(D17>2.99,0.085,IF(D17>2.49,0.06,IF(D17>1.99,0.04,IF(D17>1.49,0.02,0))))) -> 0 | G17: =IF(D17>3.99,$M$7,IF(D17>2.99,$M$6,IF(D17>2.49,$M$5,IF(D17>1.99,$M$4,IF(D17>1.49,$M$3,0))))) -> 0 | H17: =IF(D17>3.99,$N$7,IF(D17>2.99,$N$6,IF(D17>2.49,$N$5,IF(D17>1.99,$N$4,IF(D17>1.49,$N$3,IF(D17>=0,$N$2,0)))))) -> 4802.7667 | I17: =IF(D17>3.99,$N$6,IF(D17>2.99,$N$5,IF(D17>2.49,$N$4,IF(D17>1.99,$N$3,IF(D17>1.49,$N$2,IF(D17>=0,0)))))) -> 0 | J17: =B17*(E17+(B17-I17)*(F17-E17)/(H17-I17)) -> 0 | K17: =SUM(IF(O17="Yes",0,$C$12),IF(P17="Yes",0,$C$13)) -> 0 | L17: =MAX(0,K17-J17) -> 0 | N17: =MAX(0,L17*12) -> 0 | O17: =Medicaid!G9 -> Yes | P17: =Medicaid!K9 -> Yes
A18: 500 | B18: =A18/12 -> 41.666667 | C18: =B18*0.0839 -> 3.4958333 | D18: =B18/$K$2 -> 0.012926577 | E18: =IF($D$17>3.99,0.085,IF($D$17>2.99,0.06,IF($D$17>1.99,0.02,IF($D$17>1.49,0,0)))) -> 0 | F18: =IF(D18>3.99,0.085,IF(D18>2.99,0.085,IF(D18>2.49,0.06,IF(D18>1.99,0.04,IF(D18>1.49,0.02,0))))) -> 0 | G18: =IF(D18>3.99,$M$7,IF(D18>2.99,$M$6,IF(D18>2.49,$M$5,IF(D18>1.99,$M$4,IF(D18>1.49,$M$3,0))))) -> 0 | H18: =IF(D18>3.99,$N$7,IF(D18>2.99,$N$6,IF(D18>2.49,$N$5,IF(D18>1.99,$N$4,IF(D18>1.49,$N$3,IF(D18>=0,$N$2,0)))))) -> 4802.7667 | I18: =IF(D18>3.99,$N$6,IF(D18>2.99,$N$5,IF(D18>2.49,$N$4,IF(D18>1.99,$N$3,IF(D18>1.49,$N$2,IF(D18>=0,0)))))) -> 0 | J18: =B18*(E18+(B18-I18)*(F18-E18)/(H18-I18)) -> 0 | K18: =SUM(IF(O18="Yes",0,$C$12),IF(P18="Yes",0,$C$13)) -> 0 | L18: =MAX(0,K18-J18) -> 0 | N18: =MAX(0,L18*12) -> 0 | O18: =Medicaid!G10 -> Yes | P18: =Medicaid!K10 -> Yes
A19: 1000 | B19: =A19/12 -> 83.333333 | C19: =B19*0.0839 -> 6.9916667 | D19: =B19/$K$2 -> 0.025853154 | E19: =IF(D19>3.99,0.085,IF(D19>2.99,0.06,IF(D19>1.99,0.02,IF(D19>1.49,0,0)))) -> 0 | F19: =IF(D19>3.99,0.085,IF(D19>2.99,0.085,IF(D19>2.49,0.06,IF(D19>1.99,0.04,IF(D19>1.49,0.02,0))))) -> 0 | G19: =IF(D19>3.99,$M$7,IF(D19>2.99,$M$6,IF(D19>2.49,$M$5,IF(D19>1.99,$M$4,IF(D19>1.49,$M$3,0))))) -> 0 | H19: =IF(D19>3.99,$N$7,IF(D19>2.99,$N$6,IF(D19>2.49,$N$5,IF(D19>1.99,$N$4,IF(D19>1.49,$N$3,IF(D19>=0,$N$2,0)))))) -> 4802.7667 | I19: =IF(D19>3.99,$N$6,IF(D19>2.99,$N$5,IF(D19>2.49,$N$4,IF(D19>1.99,$N$3,IF(D19>1.49,$N$2,IF(D19>=0,0)))))) -> 0 | J19: =B19*(E19+(B19-I19)*(F19-E19)/(H19-I19)) -> 0 | K19: =SUM(IF(O19="Yes",0,$C$12),IF(P19="Yes",0,$C$13)) -> 0 | L19: =MAX(0,K19-J19) -> 0 | N19: =MAX(0,L19*12) -> 0 | O19: =Medicaid!G11 -> Yes | P19: =Medicaid!K11 -> Yes
A20: 1500 | B20: =A20/12 -> 125 | C20: =B20*0.0839 -> 10.4875 | D20: =B20/$K$2 -> 0.038779731 | E20: =IF(D20>3.99,0.085,IF(D20>2.99,0.06,IF(D20>1.99,0.02,IF(D20>1.49,0,0)))) -> 0 | F20: =IF(D20>3.99,0.085,IF(D20>2.99,0.085,IF(D20>2.49,0.06,IF(D20>1.99,0.04,IF(D20>1.49,0.02,0))))) -> 0 | G20: =IF(D20>3.99,$M$7,IF(D20>2.99,$M$6,IF(D20>2.49,$M$5,IF(D20>1.99,$M$4,IF(D20>1.49,$M$3,0))))) -> 0 | H20: =IF(D20>3.99,$N$7,IF(D20>2.99,$N$6,IF(D20>2.49,$N$5,IF(D20>1.99,$N$4,IF(D20>1.49,$N$3,IF(D20>=0,$N$2,0)))))) -> 4802.7667 | I20: =IF(D20>3.99,$N$6,IF(D20>2.99,$N$5,IF(D20>2.49,$N$4,IF(D20>1.99,$N$3,IF(D20>1.49,$N$2,IF(D20>=0,0)))))) -> 0 | J20: =B20*(E20+(B20-I20)*(F20-E20)/(H20-I20)) -> 0 | K20: =SUM(IF(O20="Yes",0,$C$12),IF(P20="Yes",0,$C$13)) -> 0 | L20: =MAX(0,K20-J20) -> 0 | N20: =MAX(0,L20*12) -> 0 | O20: =Medicaid!G12 -> Yes | P20: =Medicaid!K12 -> Yes
A21: 2000 | B21: =A21/12 -> 166.66667 | C21: =B21*0.0839 -> 13.983333 | D21: =B21/$K$2 -> 0.051706308 | E21: =IF(D21>3.99,0.085,IF(D21>2.99,0.06,IF(D21>1.99,0.02,IF(D21>1.49,0,0)))) -> 0 | F21: =IF(D21>3.99,0.085,IF(D21>2.99,0.085,IF(D21>2.49,0.06,IF(D21>1.99,0.04,IF(D21>1.49,0.02,0))))) -> 0 | G21: =IF(D21>3.99,$M$7,IF(D21>2.99,$M$6,IF(D21>2.49,$M$5,IF(D21>1.99,$M$4,IF(D21>1.49,$M$3,0))))) -> 0 | H21: =IF(D21>3.99,$N$7,IF(D21>2.99,$N$6,IF(D21>2.49,$N$5,IF(D21>1.99,$N$4,IF(D21>1.49,$N$3,IF(D21>=0,$N$2,0)))))) -> 4802.7667 | I21: =IF(D21>3.99,$N$6,IF(D21>2.99,$N$5,IF(D21>2.49,$N$4,IF(D21>1.99,$N$3,IF(D21>1.49,$N$2,IF(D21>=0,0)))))) -> 0 | J21: =B21*(E21+(B21-I21)*(F21-E21)/(H21-I21)) -> 0 | K21: =SUM(IF(O21="Yes",0,$C$12),IF(P21="Yes",0,$C$13)) -> 0 | L21: =MAX(0,K21-J21) -> 0 | N21: =MAX(0,L21*12) -> 0 | O21: =Medicaid!G13 -> Yes | P21: =Medicaid!K13 -> Yes
A22: 2500 | B22: =A22/12 -> 208.33333 | C22: =B22*0.0839 -> 17.479167 | D22: =B22/$K$2 -> 0.064632885 | E22: =IF(D22>3.99,0.085,IF(D22>2.99,0.06,IF(D22>1.99,0.02,IF(D22>1.49,0,0)))) -> 0 | F22: =IF(D22>3.99,0.085,IF(D22>2.99,0.085,IF(D22>2.49,0.06,IF(D22>1.99,0.04,IF(D22>1.49,0.02,0))))) -> 0 | G22: =IF(D22>3.99,$M$7,IF(D22>2.99,$M$6,IF(D22>2.49,$M$5,IF(D22>1.99,$M$4,IF(D22>1.49,$M$3,0))))) -> 0 | H22: =IF(D22>3.99,$N$7,IF(D22>2.99,$N$6,IF(D22>2.49,$N$5,IF(D22>1.99,$N$4,IF(D22>1.49,$N$3,IF(D22>=0,$N$2,0)))))) -> 4802.7667 | I22: =IF(D22>3.99,$N$6,IF(D22>2.99,$N$5,IF(D22>2.49,$N$4,IF(D22>1.99,$N$3,IF(D22>1.49,$N$2,IF(D22>=0,0)))))) -> 0 | J22: =B22*(E22+(B22-I22)*(F22-E22)/(H22-I22)) -> 0 | K22: =SUM(IF(O22="Yes",0,$C$12),IF(P22="Yes",0,$C$13)) -> 0 | L22: =MAX(0,K22-J22) -> 0 | N22: =MAX(0,L22*12) -> 0 | O22: =Medicaid!G14 -> Yes | P22: =Medicaid!K14 -> Yes
